<?xml version="1.0"?>
<robot name="open_x">

  <link name="link1">
    <inertial>
      <origin xyz="3.0876154e-04 0.0000000e+00 -1.2176461e-04" />
      <mass value="7.9119962e-02" />
      <inertia ixx="1.2505234e-05" ixy="0.0" ixz="-1.7855208e-07"
               iyy="2.1898364e-05" iyz="0.0"
               izz="1.9267361e-05" />
    </inertial>
    <visual> <geometry> <box size="0.05 0.05 0.05"/> </geometry> <material name="grey"><color rgba="0.2 0.2 0.2 1"/></material></visual>
  </link>

  <joint name="joint1" type="revolute">
    <parent link="link1"/>
    <child link="link2"/>
    <origin xyz="0.012 0.0 0.0" rpy="0 0 0"/>
    <axis xyz="0 0 1"/>
    <limit velocity="4.8" effort="1000" lower="-3.14159" upper="3.14159" />
    <dynamics damping="0.1"/>
  </joint>

  <link name="link2">
    <inertial>
      <origin xyz="-3.0184870e-04 5.4043684e-04 0.047433" />
      <mass value="9.8406837e-02" />
      <inertia ixx="3.4543422e-05" ixy="-1.6031095e-08" ixz="-3.8375155e-07"
               iyy="3.2689329e-05" iyz="2.8511935e-08"
               izz="1.8850320e-05" />
    </inertial>
    <visual> <origin xyz="0 0 0.019" rpy="0 0 0"/> <geometry> <box size="0.05 0.05 0.1"/> </geometry> <material name="grey"><color rgba="0.2 0.2 0.2 1"/></material></visual>
  </link>

  <joint name="joint2" type="revolute">
    <parent link="link2"/>
    <child link="link3"/>
    <origin xyz="0.0 0.0 0.0595" rpy="0 0 0"/>
    <axis xyz="0 1 0"/>
    <limit velocity="4.8" effort="1000" lower="-1.5" upper="1.5" />
    <dynamics damping="0.1"/>
  </joint>

  <link name="link3">
    <inertial>
      <origin xyz="1.0308393e-02 3.7743363e-04 1.0170197e-01" />
      <mass value="1.3850917e-01" />
      <inertia ixx="3.3055381e-04" ixy="-9.7940978e-08" ixz="-3.8505711e-05"
               iyy="3.4290447e-04" iyz="-1.5717516e-06"
               izz="6.0346498e-05" />
    </inertial>
    <visual> <origin xyz="0 0 0" rpy="0 0 0"/> <geometry> <box size="0.04 0.04 0.12"/> </geometry> <material name="grey"><color rgba="0.2 0.2 0.2 1"/></material></visual>
  </link>

  <joint name="joint3" type="revolute">
    <parent link="link3"/>
    <child link="link4"/>
    <origin xyz="0.024 0 0.128" rpy="0 0 0"/>
    <axis xyz="0 1 0"/>
    <limit velocity="4.8" effort="1000" lower="-1.5" upper="1.4" />
    <dynamics damping="0.1"/>
  </joint>

  <link name="link4">
    <inertial>
      <origin xyz="9.0909590e-02 3.8929816e-04 2.2413279e-04" />
      <mass value="1.3274562e-01" />
      <inertia ixx="3.0654178e-05" ixy="-1.2764155e-06" ixz="-2.6874417e-07"
               iyy="2.4230292e-04" iyz="1.1559550e-08"
               izz="2.5155057e-04" />
    </inertial>
    <visual> <origin xyz="0 0 0" rpy="0 0 0"/> <geometry> <box size="0.12 0.04 0.04"/> </geometry> <material name="grey"><color rgba="0.2 0.2 0.2 1"/></material></visual>
  </link>

  <joint name="joint4" type="revolute">
    <parent link="link4"/>
    <child link="link5"/>
    <origin xyz="0.124 0.0 0.0" rpy="0 0 0"/>
    <axis xyz="0 1 0"/>
    <limit velocity="4.8" effort="1000" lower="-1.7" upper="1.97" />
    <dynamics damping="0.1"/>
  </joint>

  <link name="link5">
    <inertial>
      <origin xyz="0.08 0.0 0.0" />
      
      <mass value="0.145" />
      
      <inertia ixx="0.0001" ixy="0.0" ixz="0.0"
               iyy="0.0001" iyz="0.0"
               izz="0.0001" />
    </inertial>

    <visual>
        <origin xyz="0 0 0" rpy="0 0 0"/>
        <geometry> <box size="0.05 0.04 0.04"/> </geometry>
        <material name="grey_motor"><color rgba="0.2 0.2 0.2 1"/></material>
    </visual>

    <visual>
        <origin xyz="0.09 0 0" rpy="0 0 0"/> 
        <geometry> <box size="0.10 0.02 0.02"/> </geometry>
        <material name="red_tool"><color rgba="1 0 0 1"/></material>
    </visual>
  </link>


  <joint name="end_effector_joint" type="fixed">
    <parent link="link5"/>
    <child link="end_effector_link"/>
    <origin xyz="0.14 0.0 0.0" rpy="0 0 0"/>
  </joint>

  <link name="end_effector_link">
    <visual>
      <geometry><sphere radius="0.005"/></geometry>
      <material name="green_tcp"><color rgba="0 1 0 0.8"/></material>
    </visual>
  </link>

</robot>